Workbook
Name asd: IBMR_Results_AWC!#REF!
Name asd_1: IBMR_Results_AWC!#REF!
Name asd_10: IBMR_Results_AWC!#REF!
Name asd_11: IBMR_Results_AWC!#REF!
Name asd_12: IBMR_Results_AWC!#REF!
Name asd_13: IBMR_Results_AWC!#REF!
Name asd_14: IBMR_Results_AWC!#REF!
Name asd_15: IBMR_Results_AWC!#REF!
Name asd_16: IBMR_Results_AWC!#REF!
Name asd_17: IBMR_Results_AWC!#REF!
Name asd_18: IBMR_Results_AWC!#REF!
Name asd_19: IBMR_Results_AWC!#REF!
Name asd_2: IBMR_Results_AWC!#REF!
Name asd_20: IBMR_Results_AWC!#REF!
Name asd_21: IBMR_Results_AWC!#REF!
Name asd_22: IBMR_Results_AWC!#REF!
Name asd_24: IBMR_Results_AWC!#REF!
Name asd_25: IBMR_Results_AWC!#REF!
Name asd_26: IBMR_Results_AWC!#REF!
Name asd_3: IBMR_Results_AWC!#REF!
Name asd_4: IBMR_Results_AWC!#REF!
Name asd_5: IBMR_Results_AWC!#REF!
Name asd_6: IBMR_Results_AWC!#REF!
Name asd_7: IBMR_Results_AWC!#REF!
Name asd_8: IBMR_Results_AWC!#REF!
Name asd_9: IBMR_Results_AWC!#REF!
Name asd1_1: IBMR_Results_AWC!#REF!
Name lam_base: IBMR_Results_AWC!#REF!
Name lam_noX2: IBMR_Results_AWC!#REF!
Name lam_summary: IBMR_Results_AWC!#REF!
Name lam_summary_base: IBMR_Results_AWC!#REF!
Name lam_summary_noX2: IBMR_Results_AWC!#REF!

Sheet IBMR_Baseline
A1: Baseline IBMR Data
A2: This worksheet displays the baseline data for IBMR 2021, as documented in Smith (2021): "A Delta Smelt Individual-Based Life Cycle Model in the R Statistical Environment, 16 August 2021" and Smith (2021): "Environmental Conditions driving habitat use: a model of the spatial distribution of delta smelt, 13 December 2021"
A9: Inputs for X2 and OMR Flows
E11: Variable: X2 | Q11: Variable: OMR Flows (cubic feet per second - cfs)
E12: Model Month | Q12: Model Month
C13: Model Year Jan. 1 to Dec. 31 | D13: Water Year Type (SVI) Oct 1 to Sept 30 | E13: J | F13: F | G13: M | H13: A | I13: M | J13: J | K13: J | L13: A | M13: S | N13: O | O13: N | P13: D | Q13: J | R13: F | S13: M | T13: A | U13: M | V13: J | W13: J | X13: A | Y13: S | Z13: O | AA13: N | AB13: D
C14: 1995 | D14: W | E14: 68.9 | F14: 53.9 | G14: 50.83 | H14: 47.68 | I14: 49.72 | J14: 55.08 | K14: 61.58 | L14: 71.17 | M14: 71.54 | N14: 71.87 | O14: 79.49 | P14: 73.19 | Q14: -7256.129 | R14: -4271.6071 | S14: 5115.9032 | T14: 6954.3333 | U14: 7361.2903 | V14: -241.05 | W14: -4934.16 | X14: -6759.066 | Y14: -4412.8777 | Z14: -3834.8065 | AA14: -3584.8524 | AB14: -2647.3869
C15: 1996 | D15: W | E15: 69.07 | F15: 55.64 | G15: 49.79 | H15: 56.52 | I15: 60.42 | J15: 65.34 | K15: 74.68 | L15: 77.26 | M15: 78.21 | N15: 84.77 | O15: 82.05 | P15: 67.47 | Q15: 22287.972 | R15: 142.13793 | S15: 4739.5414 | T15: -323.18141 | U15: -1007.8987 | V15: -7155.6667 | W15: -9025.6023 | X15: -8659.7916 | Y15: -8164.0044 | Z15: -8115.8787 | AA15: -7870 | AB15: -1411.0484
C16: 1997 | D16: W | E16: 46.52 | F16: 44.81 | G16: 55.64 | H16: 68.53 | I16: 72.31 | J16: 76.47 | K16: 77.62 | L16: 77.73 | M16: 83.35 | N16: 86.24 | O16: 83.22 | P16: 74.26 | Q16: -3268.8774 | R16: 20630.714 | S16: 966.08089 | T16: -3661.7333 | U16: -2312.6129 | V16: -5999.2793 | W16: -8660.3404 | X16: -7796.4773 | Y16: -8432.353 | Z16: -6010.0193 | AA16: -6843.976 | AB16: -8471.6129
C17: 1998 | D17: W | E17: 69.03 | F17: 48.78 | G17: 47.11 | H17: 49.36 | I17: 53.08 | J17: 53.23 | K17: 58.81 | L17: 66.1 | M17: 67.8 | N17: 71.6 | O17: 73.26 | P17: 62.35 | Q17: -1688.1993 | R17: 13019.714 | S17: 8189.3548 | T17: 9883.6667 | U17: 5840.9677 | V17: 3906.4 | W17: -897.42903 | X17: -5917.7419 | Y17: -5534.6667 | Z17: -5418.3871 | AA17: -2411.8167 | AB17: -119.53874
C18: 1999 | D18: W | E18: 64 | F18: 56.06 | G18: 52.42 | H18: 58.73 | I18: 63.94 | J18: 69.76 | K18: 74.81 | L18: 79.23 | M18: 84.49 | N18: 86.24 | O18: 83.73 | P18: 79.07 | Q18: -7390.6452 | R18: 1110.3239 | S18: -2129.5618 | T18: -1637.2855 | U18: -1062.4226 | V18: -3816.9958 | W18: -9288.7071 | X18: -9896.129 | Y18: -9534.6667 | Z18: -6773.2318 | AA18: -7055.2526 | AB18: -5164.0995
C19: 2000 | D19: W | E19: 78.42 | F19: 62.11 | G19: 51.64 | H19: 61.54 | I19: 64.77 | J19: 73.34 | K19: 77.62 | L19: 79.85 | M19: 84.07 | N19: 86.9 | O19: 85.04 | P19: 83.86 | Q19: -4560.345 | R19: -6536.6207 | S19: -2140.2516 | T19: -4253.6 | U19: -2210.1877 | V19: -6622 | W19: -9283.871 | X19: -9410.3226 | Y19: -9156 | Z19: -7663.871 | AA19: -8135 | AB19: -6681.5887
C20: 2001 | D20: D | E20: 79.65 | F20: 74.42 | G20: 67.77 | H20: 73.79 | I20: 75.59 | J20: 78.4 | K20: 82.57 | L20: 87.48 | M20: 88.2 | N20: 88.08 | O20: 84.63 | P20: 73.6 | Q20: -8369.4792 | R20: -6080.7143 | S20: -5378.2513 | T20: -2982.1962 | U20: -2069.4786 | V20: -3804.6615 | W20: -8538.5072 | X20: -8411.2903 | Y20: -7675.5654 | Z20: -4763.7562 | AA20: -6397.3496 | AB20: -8332.459
C21: 2002 | D21: D | E21: 64.19 | F21: 72.36 | G21: 71.66 | H21: 73.45 | I21: 73.82 | J21: 77.13 | K21: 81.22 | L21: 84.88 | M21: 87.84 | N21: 86.58 | O21: 84.43 | P21: 79.6 | Q21: -8365.6331 | R21: -7360.5697 | S21: -6676.109 | T21: -4220.5652 | U21: -2147.1639 | V21: -5299.4161 | W21: -10273.986 | X21: -10614.58 | Y21: -8240.1107 | Z21: -5957.8176 | AA21: -5946.1448 | AB21: -5958.323
C22: 2003 | D22: AN | E22: 62.53 | F22: 62.3 | G22: 68.51 | H22: 71 | I22: 62.66 | J22: 69.05 | K22: 76.58 | L22: 78.58 | M22: 85.6 | N22: 88.2 | O22: 84.31 | P22: 76.34 | Q22: -9286.0675 | R22: -9129.5495 | S22: -8635.5395 | T22: -4331.5497 | U22: -2742.3329 | V22: -9792.2985 | W22: -10494.353 | X22: -10501.528 | Y22: -10478.607 | Z22: -6952.3615 | AA22: -6653.3692 | AB22: -7048.5735
C23: 2004 | D23: BN | E23: 65.14 | F23: 65.59 | G23: 56.69 | H23: 64.65 | I23: 70.85 | J23: 81.14 | K23: 80.15 | L23: 82.12 | M23: 84.65 | N23: 84.04 | O23: 80.63 | P23: 81.04 | Q23: -7464.8611 | R23: -8172.7318 | S23: -8132.7572 | T23: -3838.9096 | U23: -1799.2588 | V23: -6384.6788 | W23: -9972.6826 | X23: -10739.011 | Y23: -8934.162 | Z23: -7071.9895 | AA23: -6741.6373 | AB23: -6392.4242
C24: 2005 | D24: BN | E24: 69.53 | F24: 67.51 | G24: 64.39 | H24: 62.25 | I24: 62.01 | J24: 60.96 | K24: 71.86 | L24: 79.83 | M24: 81.55 | N24: 83.55 | O24: 86.39 | P24: 78.78 | Q24: 220.44986 | R24: -4826.664 | S24: -1858.2068 | T24: -166.95101 | U24: 1959.2232 | V24: -4382.4816 | W24: -9121.2956 | X24: -9970.8339 | Y24: -9906.0522 | Z24: -10124.839 | AA24: -8316.3333 | AB24: -8057.4194
C25: 2006 | D25: W | E25: 54.66 | F25: 55.08 | G25: 52.71 | H25: 45.95 | I25: 48.35 | J25: 56.91 | K25: 69.25 | L25: 76.67 | M25: 78.87 | N25: 83.64 | O25: 86.09 | P25: 83.08 | Q25: -5045.9355 | R25: -4984.3024 | S25: 551.39258 | T25: 12837 | U25: 11486.129 | V25: 1119.471 | W25: -8064.2115 | X25: -9957.4194 | Y25: -9829.6667 | Z25: -7854.1935 | AA25: -7113.6667 | AB25: -8007.4194
... C33: 2014 | D33: C | E33: 85.39 | F33: 80.7 | G33: 76.66 | H33: 79.34 | I33: 84.15 | J33: 85.05 | K33: 85.63 | L33: 88.12 | M33: 89.49 | N33: 88.24 | O33: 84.4 | P33: 74.18 | Q33: -4155.2903 | R33: -2077.9857 | S33: -3646.9677 | T33: -3464.3667 | U33: -1818.3314 | V33: -1822.2 | W33: -2709.7486 | X33: -2956.5484 | Y33: -3912.6667 | Z33: -1235.1219 | AA33: -2358.7675 | AB33: -4891.871
A35: Inputs for Temperature, Prey (Zooplankton), Turbidity, Salinity, Delta Smelt Distribution
E36: Year | Q36: Year | AC36: Year | AO36: Year | BA36: Year | BM36: Year | BY36: Year | CK36: Year | CW36: Year | DI36: Year | DU36: Year | EG36: Year | ES36: Year | FE36: Year | FQ36: Year | GC36: Year | GO36: Year | HA36: Year | HM36: Year | HY36: Year | IK36: Year
E37: 1 | Q37: =E37+1 -> 2 | AC37: =Q37+1 -> 3 | AO37: =AC37+1 -> 4 | BA37: =AO37+1 -> 5 | BM37: =BA37+1 -> 6 | BY37: =BM37+1 -> 7 | CK37: =BY37+1 -> 8 | CW37: =CK37+1 -> 9 | DI37: =CW37+1 -> 10 | DU37: =DI37+1 -> 11 | EG37: =DU37+1 -> 12 | ES37: =EG37+1 -> 13 | FE37: =ES37+1 -> 14 | FQ37: =FE37+1 -> 15 | GC37: =FQ37+1 -> 16 | GO37: =GC37+1 -> 17 | HA37: =GO37+1 -> 18 | HM37: =HA37+1 -> 19 | HY37: =HM37+1 -> 20 | IK37: =HY37+1 -> 21
E38: Wet Year (SVI: 12.4, Wet; SJVI: 5.5, Wet) | N38: Wet Year (SVI: 9.7, Wet; SJVI: 3.9, Wet) | Z38: Wet Year (SVI: 11.0, Wet; SJVI: 4.2, Wet) | AL38: Wet Year (SVI: 12.4, Wet, SJVI: 4.9 Wet) | AX38: Wet Year (SVI: 10.0, Wet; SJVI:3.4, AN) | BJ38: Wet/AN Year (SVI: 9.2, Wet; SJVI: 3.4, Above Normal) | BV38: Dry Year (SVI: 5.9, Dry, SJVI: 2.3, Dry) | CH38: Dry Year (SVI: 6.5, Dry; SJVI: 2.3, Dry) | CT38: Above Normal/Below Normal (SVI: 8.0, AN; SJVI: 2.7, BN) | DF38: Below Normal/Dry Year (SVI: 7.7, BN; SJVI: 2.2, Dry) | DR38: Below Normal / Wet Year (SVI: 7.4, BN: SJVI, 4.2, Wet) | ED38: Wet Year (SVI: 13.0, Wet; SJVI: 5.5, Wet) | EP38: Dry / Critical Year (SVI: 6.2, Dry; SJVI: 1.9, Critical) | FB38: Critical Year (SVI: 5.4, Critical; SJVI: 2.1, Critical) | FN38: Dry Year (SVI: 5.5, Dry; SJVI: 2.4, Dry) | FZ38: Below Normal / Above Normal Year (SVI: 6.9, BN; SJVI: 3.5, AN) | GL38: Wet Year (SVI: 10.0, Wet; SJVI: 5.1, Wet) | GX38: Below Normal / Dry Year (SVI: 6.9, BN; SJVI: 2.2, Dry) | HJ38: Dry / Critical Year (SVI: 5.8, Dry; SJVI: 1.6, Critical) | HV38: Critical Year (SVI: 4.0, Critical; SJVI: 1.1, Critical) | IH38: Critical Year (SVI: 4.0, Critical; SJVI: 0.7, Critical)
E39: 1995 | F39: 1995 | G39: 1995 | H39: 1995 | I39: 1995 | J39: 1995 | K39: 1995 | L39: 1995 | M39: 1995 | N39: 1995 | O39: 1995 | P39: 1995 | Q39: =E39+1 -> 1996 | R39: =F39+1 -> 1996 | S39: =G39+1 -> 1996 | T39: =H39+1 -> 1996 | U39: =I39+1 -> 1996 | V39: =J39+1 -> 1996 | W39: =K39+1 -> 1996 | X39: =L39+1 -> 1996 | ... IK39: =HY39+1 -> 2015
A40: Strata # | B40: Strata Name | C40: Variable | D40: Metric | E40: J | F40: F | G40: M | H40: A | I40: M | J40: J | K40: J | L40: A | M40: S | N40: O | O40: N | P40: D | Q40: J | R40: F | S40: M | T40: A | U40: M | V40: J | W40: J | X40: A | Y40: S | Z40: O | AA40: N | AB40: D | AC40: J | AD40: F | AE40: M | AF40: A | AG40: M | AH40: J | AI40: J | AJ40: A | AK40: S | AL40: O | AM40: N | AN40: D | AO40: J | AP40: F | AQ40: M | AR40: A | AS40: M | AT40: J | AU40: J | AV40: A | AW40: S | AX40: O | AY40: N | AZ40: D | BA40: J | BB40: F | BC40: M | BD40: A | BE40: M | BF40: J | BG40: J | BH40: A | BI40: S | BJ40: O | BK40: N | BL40: D | BM40: J | BN40: F | BO40: M | BP40: A | BQ40: M | BR40: J | BS40: J | BT40: A | BU40: S | BV40: O | BW40: N | BX40: D | BY40: J | BZ40: F | CA40: M | CB40: A | CC40: M | CD40: J | CE40: J | CF40: A | CG40: S | CH40: O | CI40: N | CJ40: D | CK40: J | CL40: F | CM40: M | CN40: A | CO40: M | CP40: J | CQ40: J | CR40: A | CS40: S | CT40: O | CU40: N | CV40: D | CW40: J | CX40: F | CY40: M | CZ40: A | DA40: M | DB40: J | DC40: J | DD40: A | DE40: S | DF40: O | DG40: N | DH40: D | DI40: J | DJ40: F | DK40: M | DL40: A | DM40: M | DN40: J | DO40: J | DP40: A | DQ40: S | DR40: O | DS40: N | DT40: D | DU40: J | DV40: F | DW40: M | DX40: A | DY40: M | DZ40: J | EA40: J | EB40: A | EC40: S | ED40: O | EE40: N | EF40: D | EG40: J | EH40: F | EI40: M | EJ40: A | EK40: M | EL40: J | EM40: J | EN40: A | EO40: S | EP40: O | EQ40: N | ER40: D | ES40: J | ET40: F | EU40: M | EV40: A | EW40: M | EX40: J | EY40: J | EZ40: A | FA40: S | FB40: O | FC40: N | FD40: D | FE40: J | FF40: F | FG40: M | FH40: A | FI40: M | FJ40: J | FK40: J | FL40: A | FM40: S | FN40: O | FO40: N | FP40: D | FQ40: J | FR40: F | FS40: M | FT40: A | FU40: M | FV40: J | FW40: J | FX40: A | FY40: S | FZ40: O | GA40: N | GB40: D | GC40: J | GD40: F | GE40: M | GF40: A | GG40: M | GH40: J | GI40: J | GJ40: A | GK40: S | GL40: O | GM40: N | GN40: D | GO40: J | GP40: F | GQ40: M | GR40: A | GS40: M | GT40: J | GU40: J | GV40: A | GW40: S | GX40: O | GY40: N | GZ40: D | HA40: J | HB40: F | HC40: M | HD40: A | HE40: M | HF40: J | HG40: J | HH40: A | HI40: S | HJ40: O | HK40: N | HL40: D | HM40: J | HN40: F | HO40: M | HP40: A | HQ40: M | HR40: J | HS40: J | HT40: A | HU40: S | HV40: O | HW40: N | HX40: D | HY40: J | HZ40: F | IA40: M | IB40: A | IC40: M | ID40: J | IE40: J | IF40: A | IG40: S | IH40: O | II40: N | IJ40: D | IK40: J | IL40: F | IM40: M | IN40: A | IO40: M | IP40: J | IQ40: J | IR40: A | IS40: S | IT40: O | IU40: N | IV40: D
A41: 1 | B41: Yolo Bypass | C41: Temperature | D41: Degrees Celsius | E41: 12.09101 | F41: 12.558596 | G41: 14.55789 | H41: 13.849633 | I41: 16.054348 | J41: 18.66697 | K41: 21.596294 | L41: 21.774948 | M41: 20.22109 | N41: 16.695506 | O41: 14.41734 | P41: 11.982239 | Q41: 10.987506 | R41: 13.387204 | S41: 13.64351 | T41: 15.293897 | U41: 17.58549 | V41: 20.992745 | W41: 23.223487 | X41: 24.079971 | Y41: 21.437497 | Z41: 18.655506 | AA41: 13.760807 | AB41: 11.707535 | AC41: 12.241281 | AD41: 12.275207 | AE41: 14.484155 | AF41: 15.987457 | AG41: 20.083365 | AH41: 21.449443 | AI41: 22.633126 | AJ41: 23.149155 | AK41: 21.277213 | AL41: 16.852487 | AM41: 14.89429 | AN41: 10.020245 | AO41: 10.451623 | AP41: 13.217329 | AQ41: 14.536842 | AR41: 15.17536 | AS41: 17.445542 | AT41: 19.54156 | AU41: 23.543965 | AV41: 23.528887 | AW41: 22.230303 | AX41: 16.072929 | AY41: 12.997047 | AZ41: 8.8349065 | BA41: 7.9689871 | BB41: 10.95955 | BC41: 12.941335 | BD41: 14.009037 | BE41: 16.691294 | BF41: 19.991533 | BG41: 22.243458 | BH41: 21.812523 | BI41: 21.66772 | BJ41: 18.760974 | BK41: 14.987387 | BL41: 9.8737935 | BM41: 9.7649806 | BN41: 12.817825 | BO41: 13.974803 | BP41: 16.69623 | BQ41: 19.646261 | BR41: 21.682707 | BS41: 22.090771 | BT41: 22.800255 | BU41: 21.233007 | BV41: 17.688353 | BW41: 12.23062 | BX41: 9.7632419 | BY41: 8.4788935 | BZ41: 10.054168 | CA41: 14.574574 | CB41: 15.261623 | CC41: 20.204842 | CD41: 21.308017 | CE41: 22.378171 | CF41: 22.2263 | CG41: 20.98141 | CH41: 18.327916 | CI41: 15.604027 | CJ41: 10.701303 | CK41: 10.143248 | CL41: 10.33845 | CM41: 13.591432 | CN41: 16.429863 | CO41: 17.517394 | CP41: 21.408993 | CQ41: 23.620616 | CR41: 23.000381 | CS41: 22.340023 | CT41: 17.565823 | CU41: 13.769237 | CV41: 11.834687 | CW41: 11.028745 | CX41: 11.658018 | CY41: 14.749 | CZ41: 15.350693 | DA41: 17.535648 | DB41: 21.643277 | DC41: 24.059648 | DD41: 23.133274 | DE41: 21.74938 | DF41: 18.472152 | DG41: 13.524633 | DH41: 10.974026 | DI41: 9.7992194 | DJ41: 11.834125 | DK41: 15.731332 | DL41: 16.376937 | DM41: 18.574106 | DN41: 20.897666 | DO41: 22.893594 | DP41: 22.656481 | DQ41: 20.580173 | DR41: 17.402359 | DS41: 13.123363 | DT41: 10.328484 | DU41: 10.234048 | DV41: 12.763232 | DW41: 16.069155 | DX41: 15.73932 | DY41: 18.878535 | DZ41: 19.96345 | EA41: 23.710713 | EB41: 23.497652 | EC41: 20.387823 | ED41: 17.424426 | EE41: 14.49776 | EF41: 11.738232 | EG41: 11.275623 | EH41: 11.861904 | EI41: 13.153442 | EJ41: 14.813743 | EK41: 19.177703 | EL41: 21.470763 | EM41: 24.381716 | EN41: 22.558794 | EO41: 20.481677 | EP41: 16.759758 | EQ41: 14.117167 | ER41: 9.9020194 | ES41: 7.3197387 | ET41: 11.206 | EU41: 15.343119 | EV41: 16.162283 | EW41: 18.553452 | EX41: 20.859067 | EY41: 22.621435 | EZ41: 22.329916 | FA41: 21.04244 | FB41: 16.526787 | FC41: 15.227737 | FD41: 9.7524484 | FE41: 9.1515839 | FF41: 10.495964 | FG41: 14.527226 | FH41: 15.242037 | FI41: 18.218829 | FJ41: 20.222683 | FK41: 23.587335 | FL41: 22.838974 | FM41: 21.250493 | FN41: 16.898316 | FO41: 15.264767 | FP41: 10.403132 | FQ41: 8.5534161 | FR41: 11.162946 | FS41: 14.058223 | FT41: 15.30784 | FU41: 18.750371 | FV41: 20.455013 | FW41: 22.691442 | FX41: 22.520152 | FY41: 21.84852 | FZ41: 16.403729 | GA41: 12.723867 | GB41: 8.9631194 | GC41: 10.030674 | GD41: 12.149432 | GE41: 14.085877 | GF41: 15.017807 | GG41: 16.208745 | GH41: 19.998437 | GI41: 22.84661 | GJ41: 22.000861 | GK41: 20.099663 | GL41: 18.314374 | GM41: 13.709597 | GN41: 11.176368 | GO41: 8.317574 | GP41: 10.466593 | GQ41: 12.904494 | GR41: 14.34322 | GS41: 15.449687 | GT41: 18.867313 | GU41: 22.168597 | GV41: 22.493123 | GW41: 21.64608 | GX41: 20.9985 | GY41: 12.701884 | GZ41: 9.3895795 | HA41: 8.4523771 | HB41: 10.938745 | HC41: 12.537948 | HD41: 16.125893 | HE41: 18.988064 | HF41: 21.209027 | HG41: 24.025966 | HH41: 24.375686 | HI41: 22.415229 | HJ41: 19.107438 | HK41: 14.40939 | HL41: 13.37606 | HM41: 8.540863 | HN41: 10.409268 | HO41: 14.006264 | HP41: 17.038982 | HQ41: 19.619113 | HR41: 21.748784 | HS41: 23.711172 | HT41: 23.739962 | HU41: 23.133055 | HV41: 17.9913 | HW41: 14.528626 | HX41: 8.8503672 | HY41: 10.420502 | HZ41: 11.732586 | IA41: 14.358999 | IB41: 17.072625 | IC41: 19.894882 | ID41: 22.147747 | IE41: 24.451879 | IF41: 23.70316 | IG41: 23.440214 | IH41: 20.638576 | II41: 14.901581 | IJ41: 12.49597
A42: 2 | B42: Upper Sacramento | C42: Temperature | D42: Degrees Celsius | E42: 10.390894 | F42: 10.938179 | G42: 11.734219 | H42: 13.169193 | I42: 14.677742 | J42: 17.194673 | K42: 20.100648 | L42: 21.282606 | M42: 19.605127 | N42: 16.618513 | O42: 14.518143 | P42: 11.671929 | Q42: 10.44631 | R42: 11.690454 | S42: 12.490471 | T42: 14.28399 | U42: 16.559719 | V42: 19.920231 | W42: 22.064565 | X42: 22.292219 | Y42: 20.36044 | Z42: 17.429891 | AA42: 13.1209 | AB42: 11.225265 | AC42: 10.079652 | AD42: 10.760096 | AE42: 13.552752 | AF42: 15.867377 | AG42: 20.203658 | AH42: 21.480917 | AI42: 21.777887 | AJ42: 21.974742 | AK42: 21.26696 | AL42: 16.913326 | AM42: 14.245607 | AN42: 9.6448032 | AO42: 10.071952 | AP42: 10.692264 | AQ42: 12.596955 | AR42: 13.633127 | AS42: 15.318129 | AT42: 17.646917 | AU42: 21.5906 | AV42: 21.626935 | AW42: 20.117097 | AX42: 15.893755 | AY42: 12.857377 | AZ42: 9.1217065 | BA42: 8.9328194 | BB42: 9.7954036 | BC42: 11.522377 | BD42: 13.63452 | BE42: 16.992365 | BF42: 20.127007 | BG42: 21.141852 | BH42: 21.4411 | BI42: 20.799083 | BJ42: 17.611087 | BK42: 14.06593 | BL42: 9.7477194 | BM42: 9.9820323 | BN42: 11.495511 | BO42: 12.506055 | BP42: 16.004357 | BQ42: 18.505945 | BR42: 21.876648 | BS42: 21.565197 | BT42: 22.292697 | BU42: 20.64276 | BV42: 17.322659 | BW42: 12.006007 | BX42: 10.154355 | BY42: 8.8514032 | BZ42: 9.7863607 | CA42: 14.057806 | CB42: 15.700183 | CC42: 20.907042 | CD42: 21.614183 | CE42: 22.140039 | CF42: 22.394023 | CG42: 21.21845 | CH42: 18.659471 | CI42: 15.221773 | CJ42: 9.9555032 | CK42: 10.064532 | CL42: 10.563936 | CM42: 12.629303 | CN42: 16.093153 | CO42: 18.349739 | CP42: 21.577443 | CQ42: 22.352794 | CR42: 21.913468 | CS42: 21.656813 | CT42: 17.305106 | CU42: 13.630457 | CV42: 11.144806 | CW42: 10.96091 | CX42: 11.032961 | CY42: 13.912835 | CZ42: 14.82687 | DA42: 16.470684 | DB42: 20.48092 | DC42: 22.244916 | DD42: 21.699542 | DE42: 21.0526 | DF42: 18.333897 | DG42: 13.109073 | DH42: 10.697542 | DI42: 9.6350452 | DJ42: 10.805507 | DK42: 14.041826 | DL42: 15.377453 | DM42: 19.215719 | DN42: 21.255883 | DO42: 22.137752 | DP42: 21.976739 | DQ42: 20.59394 | DR42: 17.357244 | DS42: 13.046107 | DT42: 10.170894 | DU42: 9.6150226 | DV42: 11.9614 | DW42: 14.42951 | DX42: 15.195313 | DY42: 17.295732 | DZ42: 18.95848 | EA42: 22.883913 | EB42: 22.873116 | EC42: 20.028873 | ED42: 17.143684 | EE42: 13.909527 | EF42: 10.755055 | EG42: 10.656555 | EH42: 10.795725 | EI42: 11.071448 | EJ42: 12.768687 | EK42: 16.854797 | EL42: 20.00155 | EM42: 23.02111 | EN42: 21.726713 | EO42: 19.955637 | EP42: 16.731277 | EQ42: 13.774877 | ER42: 9.5033613 | ES42: 7.7734613 | ET42: 11.187004 | EU42: 13.938913 | EV42: 16.094903 | EW42: 19.562984 | EX42: 21.63832 | EY42: 22.187084 | EZ42: 22.145835 | FA42: 20.520303 | FB42: 16.660677 | FC42: 14.77568 | FD42: 9.4351516 | FE42: 8.8146516 | FF42: 9.8855607 | FG42: 13.901987 | FH42: 15.713433 | FI42: 19.171903 | FJ42: 20.877979 | FK42: 23.123755 | FL42: 23.137448 | FM42: 21.50614 | FN42: 17.502919 | FO42: 14.860053 | FP42: 9.6874032 | FQ42: 9.1522935 | FR42: 10.821529 | FS42: 13.494577 | FT42: 15.564043 | FU42: 18.365081 | FV42: 20.797643 | FW42: 21.961348 | FX42: 21.936742 | FY42: 21.746367 | FZ42: 16.783345 | GA42: 13.087617 | GB42: 9.1082323 | GC42: 9.9033871 | GD42: 11.814636 | GE42: 13.410016 | GF42: 14.651377 | GG42: 16.194703 | GH42: 19.22924 | GI42: 21.979597 | GJ42: 21.294626 | GK42: 20.02943 | GL42: 17.886877 | GM42: 13.29385 | GN42: 10.936332 | GO42: 8.6641547 | GP42: 10.135811 | GQ42: 11.201303 | GR42: 13.61641 | GS42: 15.028123 | GT42: 17.314953 | GU42: 20.776435 | GV42: 21.735052 | GW42: 20.709867 | GX42: 19.3517 | GY42: 12.184804 | GZ42: 9.2673249 | HA42: 8.8631521 | HB42: 10.957915 | HC42: 12.012048 | HD42: 15.110911 | HE42: 17.833934 | HF42: 20.397714 | HG42: 22.206958 | HH42: 21.732185 | HI42: 20.715246 | HJ42: 17.473913 | HK42: 14.100772 | HL42: 11.380468 | HM42: 8.3259296 | HN42: 10.420877 | HO42: 13.268796 | HP42: 17.106477 | HQ42: 19.508575 | HR42: 21.027442 | HS42: 23.179152 | HT42: 22.28996 | HU42: 21.638745 | HV42: 16.753388 | HW42: 13.327227 | HX42: 8.9371236 | HY42: 9.6692662 | HZ42: 11.826306 | IA42: 14.303497 | IB42: 17.025581 | IC42: 20.091224 | ID42: 22.049257 | IE42: 24.054531 | IF42: 23.26309 | IG42: 23.285764 | IH42: 19.587611 | II42: 14.739487 | IJ42: 12.559806
A43: 3 | B43: South Delta | C43: Temperature | D43: Degrees Celsius | E43: 11.396471 | F43: 12.177568 | G43: 13.888642 | H43: 14.731347 | I43: 17.520319 | J43: 19.030623 | K43: 21.862997 | L43: 21.912965 | M43: 20.29698 | N43: 16.490577 | O43: 14.48786 | P43: 11.420445 | Q43: 10.651187 | R43: 12.797589 | S43: 14.003465 | T43: 15.53019 | U43: 17.602981 | V43: 21.076676 | W43: 23.420516 | X43: 24.136794 | Y43: 21.46176 | Z43: 18.453788 | AA43: 13.525097 | AB43: 11.391248 | AC43: 10.876961 | AD43: 11.721611 | AE43: 14.252006 | AF43: 16.143093 | AG43: 20.015665 | AH43: 21.556543 | AI43: 23.024174 | AJ43: 23.372403 | AK43: 21.472867 | AL43: 16.926713 | AM43: 14.886567 | AN43: 9.8628968 | AO43: 10.622581 | AP43: 11.744346 | AQ43: 14.271965 | AR43: 15.242547 | AS43: 17.52691 | AT43: 20.075763 | AU43: 23.393371 | AV43: 23.37569 | AW43: 21.84858 | AX43: 15.894045 | AY43: 13.17403 | AZ43: 8.9073355 | BA43: 8.3570645 | BB43: 10.82125 | BC43: 12.923694 | BD43: 14.213907 | BE43: 16.802629 | BF43: 20.229797 | BG43: 22.530987 | BH43: 22.02381 | BI43: 21.74636 | BJ43: 18.793832 | BK43: 14.85785 | BL43: 9.8391774 | BM43: 10.286587 | BN43: 13.076446 | BO43: 14.145119 | BP43: 16.898457 | BQ43: 19.689713 | BR43: 22.151986 | BS43: 22.5663 | BT43: 23.0875 | BU43: 21.32012 | BV43: 17.776522 | BW43: 12.335853 | BX43: 10.015623 | BY43: 9.087571 | BZ43: 10.185282 | CA43: 15.133123 | CB43: 15.779923 | CC43: 20.424194 | CD43: 21.691633 | CE43: 22.7572 | CF43: 22.554161 | CG43: 21.235063 | CH43: 18.443271 | CI43: 15.5208 | CJ43: 10.372652 | CK43: 10.086552 | CL43: 10.759632 | CM43: 14.090039 | CN43: 16.642227 | CO43: 17.765797 | CP43: 21.54091 | CQ43: 23.763981 | CR43: 22.992971 | CS43: 22.438433 | CT43: 17.62411 | CU43: 13.855607 | CV43: 11.294639 | CW43: 10.764387 | CX43: 11.902346 | CY43: 15.033897 | CZ43: 15.571397 | DA43: 18.142448 | DB43: 21.7419 | DC43: 24.155365 | DD43: 23.146874 | DE43: 21.858473 | DF43: 18.584326 | DG43: 13.503647 | DH43: 11.020213 | DI43: 9.8772065 | DJ43: 11.795521 | DK43: 15.964029 | DL43: 16.67047 | DM43: 18.732368 | DN43: 19.4896 | DO43: 22.610894 | DP43: 22.33899 | DQ43: 20.350377 | DR43: 17.1956 | DS43: 12.8798 | DT43: 10.015594 | DU43: 10.240087 | DV43: 12.927925 | DW43: 15.746558 | DX43: 15.20699 | DY43: 18.247452 | DZ43: 19.69943 | EA43: 23.484574 | EB43: 23.512855 | EC43: 20.54856 | ED43: 17.581832 | EE43: 14.477403 | EF43: 11.181632 | EG43: 10.909681 | EH43: 11.812657 | EI43: 12.776229 | EJ43: 14.932553 | EK43: 18.833713 | EL43: 21.24792 | EM43: 24.12549 | EN43: 22.469932 | EO43: 20.51474 | EP43: 16.708768 | EQ43: 14.216987 | ER43: 9.9641194 | ES43: 7.6936419 | ET43: 11.812421 | EU43: 15.758323 | EV43: 16.44111 | EW43: 18.687939 | EX43: 20.933137 | EY43: 22.710581 | EZ43: 22.453032 | FA43: 21.173927 | FB43: 16.722974 | FC43: 15.283363 | FD43: 9.7655935 | FE43: 9.2804581 | FF43: 10.708521 | FG43: 14.950365 | FH43: 15.493807 | FI43: 18.435739 | FJ43: 20.447717 | FK43: 23.657361 | FL43: 22.915171 | FM43: 21.396503 | FN43: 17.0474 | FO43: 15.335603 | FP43: 10.371752 | FQ43: 8.9648032 | FR43: 11.224404 | FS43: 14.405906 | FT43: 15.586823 | FU43: 19.108858 | FV43: 20.637907 | FW43: 22.764394 | FX43: 22.564603 | FY43: 21.9493 | FZ43: 16.463745 | GA43: 12.9409 | GB43: 9.2171774 | GC43: 9.9040806 | GD43: 12.270457 | GE43: 14.469635 | GF43: 15.377533 | GG43: 16.355787 | GH43: 20.138657 | GI43: 22.884635 | GJ43: 22.118161 | GK43: 20.441337 | GL43: 18.469423 | GM43: 13.791547 | GN43: 11.21089 | GO43: 8.4890907 | GP43: 10.573336 | GQ43: 12.557029 | GR43: 15.29876 | GS43: 16.109577 | GT43: 18.892527 | GU43: 21.828926 | GV43: 21.716177 | GW43: 21.168347 | GX43: 20.5724 | GY43: 12.299607 | GZ43: 8.6171839 | HA43: 8.781685 | HB43: 11.370854 | HC43: 12.814741 | HD43: 16.393848 | HE43: 19.05661 | HF43: 21.212257 | HG43: 24.166009 | HH43: 24.110167 | HI43: 22.50708 | HJ43: 18.310167 | HK43: 15.426265 | HL43: 11.34569 | HM43: 7.9492539 | HN43: 10.411128 | HO43: 14.062698 | HP43: 17.284939 | HQ43: 19.089161 | HR43: 21.377116 | HS43: 24.843865 | HT43: 24.135394 | HU43: 22.597377 | HV43: 17.160018 | HW43: 13.738724 | HX43: 8.4816947 | HY43: 9.4517063 | HZ43: 11.724244 | IA43: 15.008256 | IB43: 16.612537 | IC43: 18.866543 | ID43: 22.973745 | IE43: 25.275358 | IF43: 24.79991 | IG43: 23.436901 | IH43: 19.533646 | II43: 14.906299 | IJ43: 12.584202
A44: 4 | B44: East Delta | C44: Temperature | D44: Degrees Celsius | E44: 11.140639 | F44: 11.275625 | G44: 12.446426 | H44: 13.32542 | I44: 15.08031 | J44: 17.5872 | K44: 20.512958 | L44: 21.385352 | M44: 19.734003 | N44: 16.610987 | O44: 14.55553 | P44: 11.775671 | Q44: 11.287174 | R44: 12.18595 | S44: 12.757342 | T44: 14.613247 | U44: 16.913032 | V44: 20.324234 | W44: 22.31489 | X44: 22.577003 | Y44: 20.5243 | Z44: 17.679981 | AA44: 13.16578 | AB44: 11.409319 | AC44: 10.496839 | AD44: 10.916643 | AE44: 13.858374 | AF44: 16.03044 | AG44: 20.289052 | AH44: 21.514457 | AI44: 22.094384 | AJ44: 22.249952 | AK44: 21.29368 | AL44: 16.928458 | AM44: 14.364823 | AN44: 9.6963645 | AO44: 10.757706 | AP44: 11.616454 | AQ44: 13.219868 | AR44: 14.024343 | AS44: 15.826148 | AT44: 18.318993 | AU44: 22.016335 | AV44: 21.919839 | AW44: 20.91253 | AX44: 15.969377 | AY44: 13.066403 | AZ44: 8.8720774 | BA44: 8.9591774 | BB44: 10.162082 | BC44: 11.811232 | BD44: 13.825413 | BE44: 17.062074 | BF44: 20.21288 | BG44: 21.398216 | BH44: 21.592984 | BI44: 20.974017 | BJ44: 17.837468 | BK44: 14.18395 | BL44: 9.7596903 | BM44: 10.02501 | BN44: 12.176143 | BO44: 12.893481 | BP44: 16.369907 | BQ44: 19.088671 | BR44: 22.011531 | BS44: 21.770835 | BT44: 22.469026 | BU44: 20.819397 | BV44: 17.387322 | BW44: 12.113027 | BX44: 10.174981 | BY44: 9.2218387 | BZ44: 10.003443 | CA44: 14.409274 | CB44: 15.627067 | CC44: 20.826535 | CD44: 21.6445 | CE44: 22.303358 | CF44: 22.420065 | CG44: 21.233877 | CH44: 18.589571 | CI44: 15.397997 | CJ44: 9.5839065 | CK44: 9.8850065 | CL44: 10.649575 | CM44: 13.109771 | CN44: 16.289943 | CO44: 18.157771 | CP44: 21.620443 | CQ44: 22.730574 | CR44: 22.115687 | CS44: 21.890857 | CT44: 17.320239 | CU44: 13.685627 | CV44: 10.802794 | CW44: 10.752555 | CX44: 11.4711 | CY44: 14.429565 | CZ44: 15.107617 | DA44: 17.001523 | DB44: 20.775573 | DC44: 22.636048 | DD44: 21.912735 | DE44: 21.203897 | DF44: 18.370352 | DG44: 13.171153 | DH44: 10.696887 | DI44: 9.8663258 | DJ44: 11.307121 | DK44: 14.740529 | DL44: 15.84616 | DM44: 18.959384 | DN44: 21.261724 | DO44: 22.38421 | DP44: 22.14911 | DQ44: 20.604467 | DR44: 17.394516 | DS44: 13.077407 | DT44: 10.26161 | DU44: 10.075442 | DV44: 12.522232 | DW44: 14.812852 | DX44: 15.28176 | DY44: 17.758845 | DZ44: 19.278407 | EA44: 23.056052 | EB44: 22.968277 | EC44: 20.124003 | ED44: 17.191513 | EE44: 14.012663 | EF44: 10.9153 | EG44: 10.577103 | EH44: 10.885493 | EI44: 11.517935 | EJ44: 13.22756 | EK44: 17.374745 | EL44: 20.493683 | EM44: 23.262758 | EN44: 21.856913 | EO44: 20.06386 | EP44: 16.744632 | EQ44: 13.843223 | ER44: 9.5557194 | ES44: 7.7844065 | ET44: 11.525354 | EU44: 14.548868 | EV44: 16.18447 | EW44: 19.221142 | EX44: 21.39374 | EY44: 22.344577 | EZ44: 22.249013 | FA44: 20.65425 | FB44: 16.656006 | FC44: 14.900533 | FD44: 9.5106645 | FE44: 8.8173645 | FF44: 10.09945 | FG44: 14.406019 | FH44: 15.691407 | FI44: 18.897581 | FJ44: 20.714024 | FK44: 23.261945 | FL44: 23.053426 | FM44: 21.48085 | FN44: 17.381534 | FO44: 15.020317 | FP44: 9.8864258 | FQ44: 9.197871 | FR44: 10.889307 | FS44: 13.724942 | FT44: 15.595747 | FU44: 18.634161 | FV44: 20.767143 | FW44: 22.194871 | FX44: 22.088019 | FY44: 21.78237 | FZ44: 16.689897 | GA44: 13.149013 | GB44: 9.124571 | GC44: 10.090968 | GD44: 12.321396 | GE44: 13.753335 | GF44: 14.898113 | GG44: 16.320923 | GH44: 19.546053 | GI44: 22.184413 | GJ44: 21.431842 | GK44: 20.08814 | GL44: 17.922174 | GM44: 13.34493 | GN44: 11.016681 | GO44: 8.1288497 | GP44: 10.347839 | GQ44: 11.459339 | GR44: 13.78467 | GS44: 15.209023 | GT44: 17.967093 | GU44: 21.064771 | GV44: 21.881084 | GW44: 20.883563 | GX44: 19.5885 | GY44: 13.125551 | GZ44: 8.5722021 | HA44: 8.0749285 | HB44: 11.076544 | HC44: 12.278217 | HD44: 15.290287 | HE44: 17.720487 | HF44: 20.536373 | HG44: 22.708426 | HH44: 22.259082 | HI44: 21.300483 | HJ44: 17.27449 | HK44: 15.911481 | HL44: 12.960792 | HM44: 7.6435586 | HN44: 9.9981192 | HO44: 12.907298 | HP44: 18.304633 | HQ44: 19.592752 | HR44: 20.671177 | HS44: 24.086413 | HT44: 22.933098 | HU44: 22.079345 | HV44: 16.031306 | HW44: 12.855945 | HX44: 7.3589743 | HY44: 8.9736157 | HZ44: 11.453993 | IA44: 14.638341 | IB44: 17.784144 | IC44: 19.329565 | ID44: 22.019207 | IE44: 25.382021 | IF44: 23.15777 | IG44: 23.442354 | IH44: 19.596099 | II44: 13.934369 | IJ44: 11.665184
A45: 5 | B45: Lower Sacramento | C45: Temperature | D45: Degrees Celsius | E45: 9.7315581 | F45: 10.674857 | G45: 11.242255 | H45: 13.03828 | I45: 14.983803 | J45: 17.84023 | K45: 20.705006 | L45: 21.665584 | M45: 20.020917 | N45: 16.819403 | O45: 14.57969 | P45: 11.74539 | Q45: 9.9718194 | R45: 11.204604 | S45: 12.3487 | T45: 14.55279 | U45: 16.719281 | V45: 20.406214 | W45: 22.780342 | X45: 23.657697 | Y45: 21.17933 | Z45: 18.866878 | AA45: 13.697293 | AB45: 10.9792 | AC45: 9.6511226 | AD45: 10.736968 | AE45: 13.657106 | AF45: 15.734763 | AG45: 19.857319 | AH45: 21.43443 | AI45: 22.367619 | AJ45: 22.867342 | AK45: 21.28297 | AL45: 17.146016 | AM45: 14.87345 | AN45: 9.8053258 | AO45: 9.3007065 | AP45: 10.297146 | AQ45: 12.554381 | AR45: 13.801243 | AS45: 16.123355 | AT45: 18.210283 | AU45: 22.667561 | AV45: 22.837071 | AW45: 21.32902 | AX45: 15.994106 | AY45: 13.094287 | AZ45: 9.013871 | BA45: 7.8942581 | BB45: 9.5443643 | BC45: 11.447813 | BD45: 13.614227 | BE45: 16.547252 | BF45: 19.80546 | BG45: 21.96389 | BH45: 21.476171 | BI45: 21.600397 | BJ45: 18.834674 | BK45: 15.154543 | BL45: 9.8538484 | BM45: 9.519329 | BN45: 11.032804 | BO45: 12.121271 | BP45: 16.11399 | BQ45: 18.927961 | BR45: 21.551641 | BS45: 21.935423 | BT45: 22.609639 | BU45: 21.049657 | BV45: 18.015356 | BW45: 12.596663 | BX45: 9.9547161 | BY45: 8.5437871 | BZ45: 9.1956964 | CA45: 13.75699 | CB45: 15.264677 | CC45: 20.016906 | CD45: 21.259863 | CE45: 22.273423 | CF45: 22.1293 | CG45: 21.028167 | CH45: 18.508426 | CI45: 15.81587 | CJ45: 9.7880194 | CK45: 9.5407484 | CL45: 9.8751393 | CM45: 12.960942 | CN45: 16.095637 | CO45: 17.368226 | CP45: 21.312917 | CQ45: 23.285613 | CR45: 22.72309 | CS45: 22.101553 | CT45: 17.931539 | CU45: 14.02929 | CV45: 10.965184 | CW45: 10.376613 | CX45: 11.055393 | CY45: 13.889226 | CZ45: 14.98835 | DA45: 16.737013 | DB45: 21.028083 | DC45: 23.524423 | DD45: 22.681126 | DE45: 21.634293 | DF45: 18.629081 | DG45: 14.036743 | DH45: 10.687758 | DI45: 9.1346774 | DJ45: 10.251996 | DK45: 14.01421 | DL45: 15.634713 | DM45: 18.417574 | DN45: 20.711107 | DO45: 22.60059 | DP45: 22.494887 | DQ45: 20.672597 | DR45: 17.634019 | DS45: 13.38627 | DT45: 10.10609 | DU45: 9.0177839 | DV45: 11.721875 | DW45: 14.906106 | DX45: 15.06162 | DY45: 17.846845 | DZ45: 19.341417 | EA45: 23.328529 | EB45: 23.338139 | EC45: 20.396077 | ED45: 17.450365 | EE45: 14.719457 | EF45: 10.639445 | EG45: 10.017 | EH45: 10.680557 | EI45: 10.805684 | EJ45: 12.220033 | EK45: 17.48641 | EL45: 20.570453 | EM45: 23.874735 | EN45: 22.397352 | EO45: 20.412127 | EP45: 16.932268 | EQ45: 14.38363 | ER45: 10.231645 | ES45: 7.4111032 | ET45: 10.854254 | EU45: 14.2692 | EV45: 15.932063 | EW45: 18.370861 | EX45: 20.68651 | EY45: 22.406216 | EZ45: 22.158687 | FA45: 21.14238 | FB45: 16.675919 | FC45: 15.479193 | FD45: 10.192674 | FE45: 8.4525065 | FF45: 9.6259607 | FG45: 13.836516 | FH45: 15.244143 | FI45: 17.982826 | FJ45: 19.888124 | FK45: 23.405774 | FL45: 22.709787 | FM45: 21.320837 | FN45: 17.156331 | FO45: 15.345733 | FP45: 10.932929 | FQ45: 8.3501871 | FR45: 10.338311 | FS45: 13.349587 | FT45: 15.16133 | FU45: 18.362194 | FV45: 20.265813 | FW45: 22.419681 | FX45: 22.332619 | FY45: 21.731793 | FZ45: 16.904542 | GA45: 13.248247 | GB45: 9.4214 | GC45: 9.2102774 | GD45: 11.356521 | GE45: 13.357413 | GF45: 14.72312 | GG45: 16.140445 | GH45: 19.429663 | GI45: 22.570171 | GJ45: 21.786374 | GK45: 20.084087 | GL45: 18.542787 | GM45: 14.04814 | GN45: 10.632816 | GO45: 8.2572336 | GP45: 9.8774036 | GQ45: 11.006461 | GR45: 13.605073 | GS45: 15.1875 | GT45: 17.931487 | GU45: 21.362487 | GV45: 22.266323 | GW45: 21.429017 | GX45: 20.6152 | GY45: 13.316843 | GZ45: 9.9335771 | HA45: 8.9965822 | HB45: 10.742746 | HC45: 12.193163 | HD45: 15.138858 | HE45: 18.004322 | HF45: 20.378394 | HG45: 22.590313 | HH45: 22.558345 | HI45: 21.294219 | HJ45: 18.601007 | HK45: 15.91238 | HL45: 12.565669 | HM45: 7.9457421 | HN45: 10.531715 | HO45: 13.815855 | HP45: 16.770874 | HQ45: 19.072637 | HR45: 20.037866 | HS45: 24.039174 | HT45: 22.179834 | HU45: 21.628075 | HV45: 17.070788 | HW45: 14.627175 | HX45: 10.362986 | HY45: 9.4549126 | HZ45: 10.742033 | IA45: 14.491555 | IB45: 16.754184 | IC45: 19.051954 | ID45: 21.451323 | IE45: 23.401106 | IF45: 22.416353 | IG45: 22.592495 | IH45: 20.255136 | II45: 16.169854 | IJ45: 13.423704
A46: 6 | B46: Lower San Joaquin | C46: Temperature | D46: Degrees Celsius | E46: 10.288771 | F46: 11.518082 | G46: 13.039377 | H46: 13.932143 | I46: 16.530658 | J46: 18.596063 | K46: 21.362223 | L46: 21.712294 | M46: 20.144493 | N46: 16.709097 | O46: 14.49539 | P46: 11.819632 | Q46: 10.162261 | R46: 12.291361 | S46: 13.486135 | T46: 15.193197 | U46: 17.443539 | V46: 20.724145 | W46: 23.063968 | X46: 23.918474 | Y46: 21.284617 | Z46: 18.725081 | AA46: 13.649577 | AB46: 11.256152 | AC46: 10.413361 | AD46: 11.605804 | AE46: 14.019877 | AF46: 15.9199 | AG46: 20.062219 | AH46: 21.548037 | AI46: 22.65499 | AJ46: 23.093019 | AK46: 21.311413 | AL46: 17.0161 | AM46: 14.880547 | AN46: 9.8273903 | AO46: 9.6158226 | AP46: 11.440857 | AQ46: 14.078332 | AR46: 15.025477 | AS46: 17.358539 | AT46: 19.687787 | AU46: 23.474594 | AV46: 23.315445 | AW46: 21.974807 | AX46: 16.069803 | AY46: 13.101397 | AZ46: 8.9200129 | BA46: 7.7384387 | BB46: 10.223293 | BC46: 12.380984 | BD46: 13.862693 | BE46: 16.674771 | BF46: 20.042393 | BG46: 22.290571 | BH46: 21.716268 | BI46: 21.680267 | BJ46: 18.780271 | BK46: 15.005937 | BL46: 9.864771 | BM46: 9.5569355 | BN46: 11.927746 | BO46: 13.437445 | BP46: 16.5395 | BQ46: 19.553268 | BR46: 21.835538 | BS46: 22.243681 | BT46: 22.88129 | BU46: 21.212243 | BV46: 17.891731 | BW46: 12.441187 | BX46: 9.8276419 | BY46: 8.5405161 | BZ46: 9.334425 | CA46: 14.109394 | CB46: 15.29127 | CC46: 20.254565 | CD46: 21.46568 | CE46: 22.506974 | CF46: 22.298645 | CG46: 21.065057 | CH46: 18.419784 | CI46: 15.713043 | CJ46: 9.9594871 | CK46: 9.5157419 | CL46: 9.9079643 | CM46: 13.412394 | CN46: 16.28861 | CO46: 17.453068 | CP46: 21.41351 | CQ46: 23.527448 | CR46: 22.880497 | CS46: 22.2261 | CT46: 17.69501 | CU46: 13.88422 | CV46: 11.087239 | CW46: 10.274239 | CX46: 11.380461 | CY46: 14.364123 | CZ46: 15.253723 | DA46: 17.378771 | DB46: 21.44187 | DC46: 23.874245 | DD46: 22.914339 | DE46: 21.685647 | DF46: 18.522019 | DG46: 13.745387 | DH46: 10.75179 | DI46: 9.1269032 | DJ46: 10.721464 | DK46: 14.930187 | DL46: 16.143323 | DM46: 18.468674 | DN46: 20.813272 | DO46: 22.79751 | DP46: 22.594229 | DQ46: 20.623307 | DR46: 17.502666 | DS46: 13.19694 | DT46: 9.9514677 | DU46: 9.3243161 | DV46: 12.006511 | DW46: 15.6206 | DX46: 15.36167 | DY46: 18.738381 | DZ46: 19.766863 | EA46: 23.541061 | EB46: 23.425119 | EC46: 20.385967 | ED46: 17.409397 | EE46: 14.591547 | EF46: 10.844271 | EG46: 10.578203 | EH46: 11.269593 | EI46: 12.153845 | EJ46: 14.58022 | EK46: 19.105223 | EL46: 21.27336 | EM46: 24.152313 | EN46: 22.4899 | EO46: 20.466943 | EP46: 16.805952 | EQ46: 14.234763 | ER46: 10.0668 | ES46: 7.3209806 | ET46: 10.993829 | EU46: 14.971635 | EV46: 16.14244 | EW46: 18.490952 | EX46: 20.78632 | EY46: 22.563187 | EZ46: 22.265255 | FA46: 21.121327 | FB46: 16.580658 | FC46: 15.347747 | FD46: 9.9478323 | FE46: 8.5641258 | FF46: 9.8872429 | FG46: 14.225387 | FH46: 15.271347 | FI46: 18.13801 | FJ46: 20.1069 | FK46: 23.54791 | FL46: 22.796145 | FM46: 21.32006 | FN46: 17.055212 | FO46: 15.33252 | FP46: 10.712594 | FQ46: 8.3610613 | FR46: 10.481161 | FS46: 13.670374 | FT46: 15.241337 | FU46: 18.657455 | FV46: 20.403083 | FW46: 22.598603 | FX46: 22.438629 | FY46: 21.80013 | FZ46: 16.622755 | GA46: 13.031587 | GB46: 9.2081161 | GC46: 9.3359355 | GD46: 11.432729 | GE46: 13.776587 | GF46: 14.968657 | GG46: 16.2725 | GH46: 19.840057 | GI46: 22.749584 | GJ46: 21.909161 | GK46: 20.116983 | GL46: 18.399329 | GM46: 13.874867 | GN46: 10.703368 | GO46: 8.3670018 | GP46: 10.066393 | GQ46: 11.884381 | GR46: 14.63164 | GS46: 15.573145 | GT46: 18.73461 | GU46: 21.895152 | GV46: 22.390635 | GW46: 21.560347 | GX46: 20.885 | GY46: 13.443548 | GZ46: 9.800408 | HA46: 8.883747 | HB46: 10.591253 | HC46: 12.266805 | HD46: 15.353944 | HE46: 18.762964 | HF46: 20.134104 | HG46: 22.565693 | HH46: 22.404255 | HI46: 21.734848 | HJ46: 18.867164 | HK46: 17.069789 | HL46: 13.497008 | HM46: 8.038981 | HN46: 10.034067 | HO46: 13.065638 | HP46: 16.770446 | HQ46: 19.362089 | HR46: 20.146942 | HS46: 23.712841 | HT46: 21.941085 | HU46: 22.231731 | HV46: 17.50838 | HW46: 14.643334 | HX46: 10.204817 | HY46: 8.8729628 | HZ46: 10.986675 | IA46: 14.178299 | IB46: 16.132806 | IC46: 19.188343 | ID46: 21.487484 | IE46: 23.427376 | IF46: 23.539712 | IG46: 23.219259 | IH46: 19.933107 | II46: 16.351838 | IJ46: 13.256609
A47: 7 | B47: Confluence | C47: Temperature | D47: Degrees Celsius | E47: 9.728729 | F47: 10.852311 | G47: 11.702765 | H47: 13.242057 | I47: 15.402806 | J47: 18.060857 | K47: 20.941394 | L47: 21.668997 | M47: 20.121297 | N47: 16.961416 | O47: 14.652763 | P47: 11.95219 | Q47: 9.9339774 | R47: 11.466268 | S47: 12.621797 | T47: 14.766293 | U47: 16.899887 | V47: 20.497124 | W47: 22.753297 | X47: 23.865268 | Y47: 21.335677 | Z47: 18.939594 | AA47: 14.00791 | AB47: 11.143674 | AC47: 9.824629 | AD47: 11.018525 | AE47: 13.681245 | AF47: 15.755003 | AG47: 19.798874 | AH47: 21.477387 | AI47: 22.417568 | AJ47: 23.031945 | AK47: 21.287317 | AL47: 17.313094 | AM47: 15.08208 | AN47: 10.06301 | AO47: 9.2438839 | AP47: 10.579007 | AQ47: 13.013803 | AR47: 14.15474 | AS47: 16.6239 | AT47: 18.67365 | AU47: 22.9972 | AV47: 23.252213 | AW47: 21.82616 | AX47: 16.146565 | AY47: 13.230257 | AZ47: 9.0981194 | BA47: 7.6851452 | BB47: 9.6821286 | BC47: 11.702739 | BD47: 13.628087 | BE47: 16.4067 | BF47: 19.716443 | BG47: 22.196365 | BH47: 21.413094 | BI47: 21.639173 | BJ47: 18.958468 | BK47: 15.47882 | BL47: 10.148081 | BM47: 9.4497419 | BN47: 11.240675 | BO47: 12.426481 | BP47: 16.193397 | BQ47: 19.100977 | BR47: 21.527079 | BS47: 22.067542 | BT47: 22.711658 | BU47: 21.071327 | BV47: 18.218 | BW47: 12.90148 | BX47: 10.056816 | BY47: 8.6238613 | BZ47: 9.2194679 | CA47: 13.624142 | CB47: 15.253743 | CC47: 19.869761 | CD47: 21.284283 | CE47: 22.300694 | CF47: 22.013984 | CG47: 20.92279 | CH47: 18.413794 | CI47: 15.930297 | CJ47: 9.9995774 | CK47: 9.5777516 | CL47: 9.6833679 | CM47: 13.084652 | CN47: 16.099453 | CO47: 17.166619 | CP47: 21.141493 | CQ47: 23.204881 | CR47: 22.770148 | CS47: 21.92056 | CT47: 18.053171 | CU47: 14.180487 | CV47: 11.135419 | CW47: 10.299145 | CX47: 11.185196 | CY47: 13.938642 | CZ47: 15.134097 | DA47: 16.852068 | DB47: 21.189867 | DC47: 23.626252 | DD47: 22.910558 | DE47: 21.677557 | DF47: 18.657494 | DG47: 14.318077 | DH47: 10.876023 | DI47: 9.0988581 | DJ47: 10.322707 | DK47: 14.172594 | DL47: 15.83498 | DM47: 18.289529 | DN47: 20.565214 | DO47: 22.545042 | DP47: 22.482403 | DQ47: 20.707667 | DR47: 17.702359 | DS47: 13.615087 | DT47: 10.213868 | DU47: 9.0070774 | DV47: 11.641604 | DW47: 15.161739 | DX47: 15.077127 | DY47: 18.167048 | DZ47: 19.472997 | EA47: 23.20769 | EB47: 23.301329 | EC47: 20.40257 | ED47: 17.552642 | EE47: 14.946293 | EF47: 10.937997 | EG47: 10.1385 | EH47: 10.873646 | EI47: 11.148574 | EJ47: 12.955673 | EK47: 18.168065 | EL47: 20.731487 | EM47: 23.910239 | EN47: 22.550329 | EO47: 20.49601 | EP47: 16.987735 | EQ47: 14.601217 | ER47: 10.558787 | ES47: 7.5202097 | ET47: 10.713314 | EU47: 14.280623 | EV47: 16.0401 | EW47: 18.168755 | EX47: 20.471967 | EY47: 22.322532 | EZ47: 22.032068 | FA47: 21.205267 | FB47: 16.753432 | FC47: 15.507873 | FD47: 10.542661 | FE47: 8.4687 | FF47: 9.5563571 | FG47: 13.784381 | FH47: 15.160307 | FI47: 17.806377 | FJ47: 19.708659 | FK47: 23.17229 | FL47: 22.496265 | FM47: 21.07091 | FN47: 17.030638 | FO47: 15.0992 | FP47: 10.994968 | FQ47: 8.2959935 | FR47: 10.246918 | FS47: 13.290029 | FT47: 15.083807 | FU47: 18.287906 | FV47: 20.14235 | FW47: 22.296552 | FX47: 22.228832 | FY47: 21.611493 | FZ47: 16.966516 | GA47: 13.44215 | GB47: 9.6297548 | GC47: 9.1470516 | GD47: 11.210525 | GE47: 13.369142 | GF47: 14.792717 | GG47: 16.110781 | GH47: 19.44501 | GI47: 22.419439 | GJ47: 21.721819 | GK47: 20.076653 | GL47: 18.625474 | GM47: 14.382357 | GN47: 10.76759 | GO47: 8.1250279 | GP47: 9.8749821 | GQ47: 11.212755 | GR47: 13.871757 | GS47: 15.243226 | GT47: 18.153783 | GU47: 21.511787 | GV47: 22.228639 | GW47: 21.56905 | GX47: 20.927 | GY47: 13.729841 | GZ47: 9.9460951 | HA47: 9.0267108 | HB47: 10.861031 | HC47: 12.074259 | HD47: 14.773024 | HE47: 18.575528 | HF47: 19.79236 | HG47: 22.05056 | HH47: 21.581245 | HI47: 20.746157 | HJ47: 18.080409 | HK47: 15.62008 | HL47: 13.098036 | HM47: 7.9111404 | HN47: 10.313831 | HO47: 13.4158 | HP47: 17.113261 | HQ47: 18.883461 | HR47: 19.404699 | HS47: 22.274732 | HT47: 21.058081 | HU47: 21.765476 | HV47: 17.443598 | HW47: 14.664476 | HX47: 10.499809 | HY47: 9.6557919 | HZ47: 11.187554 | IA47: 14.551284 | IB47: 16.593306 | IC47: 19.064696 | ID47: 20.54753 | IE47: 22.257258 | IF47: 21.690086 | IG47: 21.676644 | IH47: 20.298496 | II47: 16.772646 | IJ47: 13.52785
A48: 8 | B48: South Suisun East | C48: Temperature | D48: Degrees Celsius | E48: 9.6506871 | F48: 10.658996 | G48: 11.414768 | H48: 13.00964 | I48: 15.052842 | J48: 18.055593 | K48: 21.065061 | L48: 21.706642 | M48: 20.165213 | N48: 17.260181 | O48: 14.85593 | P48: 12.247203 | Q48: 9.943 | R48: 11.215725 | S48: 12.379226 | T48: 14.762613 | U48: 16.919484 | V48: 20.431641 | W48: 22.44061 | X48: 23.342187 | Y48: 21.061773 | Z48: 18.498866 | AA48: 13.987477 | AB48: 11.175861 | AC48: 9.7172032 | AD48: 10.8207 | AE48: 13.537865 | AF48: 15.904303 | AG48: 19.761877 | AH48: 21.522097 | AI48: 22.201648 | AJ48: 22.59111 | AK48: 21.224297 | AL48: 17.502087 | AM48: 15.2337 | AN48: 10.322513 | AO48: 9.2226 | AP48: 10.362386 | AQ48: 12.632065 | AR48: 13.81161 | AS48: 16.509158 | AT48: 18.35823 | AU48: 22.731106 | AV48: 23.210965 | AW48: 21.86895 | AX48: 16.415697 | AY48: 13.361413 | AZ48: 9.2567387 | BA48: 7.7216419 | BB48: 9.5198964 | BC48: 11.485306 | BD48: 13.605093 | BE48: 16.401106 | BF48: 19.552093 | BG48: 22.019403 | BH48: 21.209677 | BI48: 21.04405 | BJ48: 18.78289 | BK48: 15.460113 | BL48: 10.448071 | BM48: 9.5809645 | BN48: 11.096054 | BO48: 12.132187 | BP48: 16.082877 | BQ48: 18.902445 | BR48: 21.294652 | BS48: 21.757526 | BT48: 22.323326 | BU48: 20.745097 | BV48: 18.157147 | BW48: 13.078193 | BX48: 10.361477 | BY48: 8.8355226 | BZ48: 9.3781429 | CA48: 13.394832 | CB48: 15.28784 | CC48: 19.676806 | CD48: 21.309613 | CE48: 21.948835 | CF48: 21.547826 | CG48: 20.5183 | CH48: 18.168855 | CI48: 15.941447 | CJ48: 10.316926 | CK48: 9.7615355 | CL48: 9.7721071 | CM48: 13.104381 | CN48: 16.06764 | CO48: 17.15139 | CP48: 20.902603 | CQ48: 22.646768 | CR48: 22.081716 | CS48: 21.31249 | CT48: 17.864826 | CU48: 14.319257 | CV48: 11.308932 | CW48: 10.274006 | CX48: 11.268725 | CY48: 13.975742 | CZ48: 15.268943 | DA48: 16.790794 | DB48: 21.05319 | DC48: 23.281987 | DD48: 22.750126 | DE48: 21.473853 | DF48: 18.613768 | DG48: 14.4532 | DH48: 11.048668 | DI48: 9.1205613 | DJ48: 10.350518 | DK48: 13.985148 | DL48: 16.021907 | DM48: 18.482097 | DN48: 20.520359 | DO48: 22.210865 | DP48: 22.13279 | DQ48: 20.87987 | DR48: 17.7481 | DS48: 13.889517 | DT48: 10.439135 | DU48: 9.0353452 | DV48: 11.465779 | DW48: 14.9996 | DX48: 15.073773 | DY48: 17.97039 | DZ48: 19.575107 | EA48: 22.808681 | EB48: 22.604152 | EC48: 20.134683 | ED48: 17.708548 | EE48: 15.057013 | EF48: 11.16721 | EG48: 10.085623 | EH48: 10.844882 | EI48: 10.883042 | EJ48: 12.35439 | EK48: 17.824974 | EL48: 20.614467 | EM48: 23.578545 | EN48: 22.237123 | EO48: 20.216907 | EP48: 17.052558 | EQ48: 14.893733 | ER48: 10.748729 | ES48: 7.8929935 | ET48: 10.694418 | EU48: 14.150939 | EV48: 16.005557 | EW48: 17.9907 | EX48: 20.273163 | EY48: 22.1118 | EZ48: 21.710248 | FA48: 21.016457 | FB48: 16.837961 | FC48: 15.337127 | FD48: 10.603006 | FE48: 8.4264935 | FF48: 9.4324036 | FG48: 13.549116 | FH48: 15.059317 | FI48: 17.796977 | FJ48: 19.804028 | FK48: 22.442074 | FL48: 21.880203 | FM48: 20.135473 | FN48: 16.385713 | FO48: 14.066653 | FP48: 10.373042 | FQ48: 8.4474 | FR48: 10.256036 | FS48: 13.165803 | FT48: 15.165733 | FU48: 18.192568 | FV48: 19.987267 | FW48: 21.855445 | FX48: 21.672971 | FY48: 21.269413 | FZ48: 17.009452 | GA48: 13.743197 | GB48: 9.8015935 | GC48: 9.2242839 | GD48: 11.068425 | GE48: 13.336832 | GF48: 14.826233 | GG48: 16.216926 | GH48: 19.54227 | GI48: 21.820874 | GJ48: 21.065439 | GK48: 19.958093 | GL48: 18.560842 | GM48: 14.521457 | GN48: 10.828277 | GO48: 9.0454456 | GP48: 9.9087536 | GQ48: 10.983342 | GR48: 13.65482 | GS48: 15.284539 | GT48: 18.10525 | GU48: 21.454571 | GV48: 21.783835 | GW48: 21.281227 | GX48: 20.8216 | GY48: 14.092175 | GZ48: 9.9583641 | HA48: 9.4719659 | HB48: 10.983291 | HC48: 12.282325 | HD48: 15.139307 | HE48: 18.363509 | HF48: 19.706586 | HG48: 21.666028 | HH48: 21.406191 | HI48: 20.094488 | HJ48: 17.767494 | HK48: 15.468517 | HL48: 11.844322 | HM48: 8.0827431 | HN48: 10.462645 | HO48: 13.538228 | HP48: 16.703942 | HQ48: 18.766429 | HR48: 19.619865 | HS48: 22.026497 | HT48: 21.30788 | HU48: 21.659222 | HV48: 16.950193 | HW48: 14.320522 | HX48: 10.144251 | HY48: 9.8580426 | HZ48: 11.93869 | IA48: 14.741181 | IB48: 16.819284 | IC48: 18.836126 | ID48: 20.430328 | IE48: 22.186109 | IF48: 21.9469 | IG48: 21.561456 | IH48: 19.406264 | II48: 16.217446 | IJ48: 13.334813
A49: 9 | B49: North Suisun East | C49: Temperature | D49: Degrees Celsius | E49: 9.6791258 | F49: 10.753368 | G49: 11.526442 | H49: 13.114863 | I49: 15.281555 | J49: 18.19913 | K49: 21.204365 | L49: 21.710594 | M49: 20.154777 | N49: 17.043223 | O49: 14.71643 | P49: 12.095194 | Q49: 9.870229 | R49: 11.326446 | S49: 12.486632 | T49: 14.877773 | U49: 17.028013 | V49: 20.605272 | W49: 22.795684 | X49: 23.654165 | Y49: 21.182587 | Z49: 18.527881 | AA49: 13.920137 | AB49: 11.090023 | AC49: 9.7105194 | AD49: 10.848036 | AE49: 13.721835 | AF49: 15.913653 | AG49: 19.936081 | AH49: 21.56461 | AI49: 22.49369 | AJ49: 22.864419 | AK49: 21.227217 | AL49: 17.293226 | AM49: 15.136993 | AN49: 10.152652 | AO49: 9.1974871 | AP49: 10.387725 | AQ49: 12.819435 | AR49: 14.03152 | AS49: 16.669261 | AT49: 18.683227 | AU49: 23.098106 | AV49: 23.438271 | AW49: 21.99263 | AX49: 16.24329 | AY49: 13.25115 | AZ49: 9.0697194 | BA49: 7.6193 | BB49: 9.5931964 | BC49: 11.644155 | BD49: 13.644337 | BE49: 16.533319 | BF49: 19.80151 | BG49: 22.2461 | BH49: 21.453835 | BI49: 21.252403 | BJ49: 18.737881 | BK49: 15.355877 | BL49: 10.267661 | BM49: 9.5158226 | BN49: 11.190564 | BO49: 12.3008 | BP49: 16.272293 | BQ49: 19.248587 | BR49: 21.602052 | BS49: 22.044935 | BT49: 22.594074 | BU49: 20.897347 | BV49: 18.01205 | BW49: 12.891693 | BX49: 10.180445 | BY49: 8.7024548 | BZ49: 9.346975 | CA49: 13.626423 | CB49: 15.302153 | CC49: 19.9364 | CD49: 21.430573 | CE49: 22.234435 | CF49: 21.832442 | CG49: 20.656337 | CH49: 18.122458 | CI49: 15.80061 | CJ49: 10.143487 | CK49: 9.6018645 | CL49: 9.7981321 | CM49: 13.237097 | CN49: 16.146433 | CO49: 17.321535 | CP49: 21.14298 | CQ49: 23.108129 | CR49: 22.428061 | CS49: 21.605353 | CT49: 17.734245 | CU49: 14.154347 | CV49: 11.161323 | CW49: 10.247465 | CX49: 11.280793 | CY49: 14.142365 | CZ49: 15.28085 | DA49: 17.030545 | DB49: 21.376147 | DC49: 23.712784 | DD49: 22.941784 | DE49: 21.550777 | DF49: 18.493116 | DG49: 14.245643 | DH49: 10.946203 | DI49: 9.0444903 | DJ49: 10.346061 | DK49: 14.211077 | DL49: 16.11527 | DM49: 18.468352 | DN49: 20.701234 | DO49: 22.536806 | DP49: 22.355435 | DQ49: 20.745147 | DR49: 17.61585 | DS49: 13.658893 | DT49: 10.216 | DU49: 8.9912097 | DV49: 11.547686 | DW49: 15.188819 | DX49: 15.172217 | DY49: 18.249535 | DZ49: 19.703 | EA49: 23.194745 | EB49: 22.964545 | EC49: 20.177863 | ED49: 17.556694 | EE49: 14.894263 | EF49: 11.113606 | EG49: 10.058806 | EH49: 10.904475 | EI49: 11.055639 | EJ49: 12.600837 | EK49: 18.145665 | EL49: 20.916893 | EM49: 23.936332 | EN49: 22.406497 | EO49: 20.293707 | EP49: 16.894226 | EQ49: 14.691317 | ER49: 10.577603 | ES49: 7.6974387 | ET49: 10.784039 | EU49: 14.431448 | EV49: 16.10928 | EW49: 18.200639 | EX49: 20.506533 | EY49: 22.3602 | EZ49: 21.956535 | FA49: 20.9834 | FB49: 16.708816 | FC49: 15.265223 | FD49: 10.408487 | FE49: 8.4056 | FF49: 9.5113107 | FG49: 13.774397 | FH49: 15.148187 | FI49: 17.935477 | FJ49: 19.983434 | FK49: 22.893842 | FL49: 22.240784 | FM49: 20.440817 | FN49: 16.467803 | FO49: 14.280917 | FP49: 10.319113 | FQ49: 8.3706516 | FR49: 10.292782 | FS49: 13.329877 | FT49: 15.185633 | FU49: 18.464594 | FV49: 20.175193 | FW49: 22.193223 | FX49: 21.955265 | FY49: 21.382363 | FZ49: 16.737029 | GA49: 13.521297 | GB49: 9.6509935 | GC49: 9.1653065 | GD49: 11.1017 | GE49: 13.479003 | GF49: 14.861597 | GG49: 16.239871 | GH49: 19.763913 | GI49: 22.224277 | GJ49: 21.34689 | GK49: 19.983333 | GL49: 18.436026 | GM49: 14.35247 | GN49: 10.785094 | GO49: 8.1228584 | GP49: 9.8867964 | GQ49: 11.120839 | GR49: 13.732743 | GS49: 15.305732 | GT49: 18.350537 | GU49: 21.701274 | GV49: 22.030881 | GW49: 21.416667 | GX49: 20.8373 | GY49: 13.949348 | GZ49: 9.920233 | HA49: 9.4109769 | HB49: 10.81892 | HC49: 12.244837 | HD49: 15.092896 | HE49: 18.584938 | HF49: 19.567788 | HG49: 21.24485 | HH49: 21.14471 | HI49: 19.742758 | HJ49: 17.154665 | HK49: 14.952882 | HL49: 13.110573 | HM49: 8.5722021 | HN49: 10.429489 | HO49: 13.420834 | HP49: 17.17753 | HQ49: 18.88878 | HR49: 19.517861 | HS49: 22.182052 | HT49: 21.180658 | HU49: 21.555111 | HV49: 17.094753 | HW49: 14.533494 | HX49: 9.3510644 | HY49: 9.920233 | HZ49: 11.897345 | IA49: 14.976847 | IB49: 16.771872 | IC49: 19.162666 | ID49: 20.386592 | IE49: 22.068111 | IF49: 21.180658 | IG49: 21.360395 | IH49: 19.476274 | II49: 16.840125 | IJ49: 14.044977
A50: 10 | B50: Suisun Marsh | C50: Temperature | D50: Degrees Celsius | E50: 9.9130613 | F50: 11.979839 | G50: 13.183481 | H50: 13.874197 | I50: 16.606694 | J50: 19.019627 | K50: 21.831161 | L50: 21.595642 | M50: 20.05031 | N50: 16.333326 | O50: 14.197527 | P50: 11.345284 | Q50: 9.6652452 | R50: 12.508286 | S50: 13.551384 | T50: 15.626913 | U50: 17.964719 | V50: 21.216466 | W50: 23.505829 | X50: 24.028913 | Y50: 21.164403 | Z50: 18.155487 | AA50: 13.324733 | AB50: 10.555974 | AC50: 9.7538839 | AD50: 11.572896 | AE50: 14.956719 | AF50: 16.202873 | AG50: 20.449948 | AH50: 21.568197 | AI50: 22.984081 | AJ50: 23.109129 | AK50: 21.01804 | AL50: 16.398381 | AM50: 14.68004 | AN50: 9.0477032 | AO50: 9.1711839 | AP50: 10.849943 | AQ50: 14.625965 | AR50: 15.479257 | AS50: 17.724419 | AT50: 20.36657 | AU50: 24.070197 | AV50: 23.82731 | AW50: 22.150333 | AX50: 15.591132 | AY50: 12.659353 | AZ50: 7.8403613 | BA50: 7.1066806 | BB50: 10.265339 | BC50: 13.082345 | BD50: 14.16839 | BE50: 16.973861 | BF50: 20.303283 | BG50: 22.449758 | BH50: 21.874932 | BI50: 21.386013 | BJ50: 18.367926 | BK50: 14.55501 | BL50: 9.2194645 | BM50: 9.4481194 | BN50: 12.048054 | BO50: 13.947271 | BP50: 17.016483 | BQ50: 20.218616 | BR50: 22.114369 | BS50: 22.328403 | BT50: 22.862761 | BU50: 21.00905 | BV50: 17.128637 | BW50: 11.75637 | BX50: 9.3739839 | BY50: 8.0701935 | BZ50: 9.4789 | CA50: 14.975074 | CB50: 15.319577 | CC50: 20.580539 | CD50: 21.654543 | CE50: 22.576739 | CF50: 22.132577 | CG50: 20.560653 | CH50: 17.732426 | CI50: 15.134567 | CJ50: 9.3640452 | CK50: 8.974629 | CL50: 10.332079 | CM50: 14.041984 | CN50: 16.58365 | CO50: 17.788948 | CP50: 21.502073 | CQ50: 23.797197 | CR50: 22.699839 | CS50: 22.001213 | CT50: 16.953755 | CU50: 13.340673 | CV50: 10.417042 | CW50: 10.076145 | CX50: 11.608071 | CY50: 15.247726 | CZ50: 15.421983 | DA50: 18.127358 | DB50: 21.93338 | DC50: 24.390326 | DD50: 23.006174 | DE50: 21.430947 | DF50: 17.990584 | DG50: 12.912687 | DH50: 10.449494 | DI50: 8.8338516 | DJ50: 10.8081 | DK50: 16.140303 | DL50: 16.623763 | DM50: 18.627397 | DN50: 20.998434 | DO50: 22.983584 | DP50: 22.463555 | DQ50: 20.19804 | DR50: 16.930725 | DS50: 12.626607 | DT50: 9.2635097 | DU50: 8.9008645 | DV50: 12.175568 | DW50: 16.425813 | DX50: 15.84355 | DY50: 19.4601 | DZ50: 20.195093 | EA50: 23.902032 | EB50: 23.161732 | EC50: 19.855487 | ED50: 17.012877 | EE50: 14.080833 | EF50: 10.764103 | EG50: 10.114316 | EH50: 11.708332 | EI50: 12.706532 | EJ50: 15.016717 | EK50: 19.996732 | EL50: 21.978577 | EM50: 24.569713 | EN50: 22.254594 | EO50: 20.036967 | EP50: 16.185694 | EQ50: 13.834047 | ER50: 9.4810677 | ES50: 6.9878516 | ET50: 11.541179 | EU50: 16.080213 | EV50: 16.362523 | EW50: 18.657648 | EX50: 20.84453 | EY50: 22.672268 | EZ50: 22.163081 | FA50: 20.558677 | FB50: 16.085839 | FC50: 14.69417 | FD50: 9.1621806 | FE50: 8.2473677 | FF50: 10.221032 | FG50: 14.966168 | FH50: 15.349267 | FI50: 18.338197 | FJ50: 20.446417 | FK50: 23.489394 | FL50: 22.552035 | FM50: 20.55014 | FN50: 16.227347 | FO50: 14.479253 | FP50: 9.4465419 | FQ50: 8.1611645 | FR50: 10.649657 | FS50: 14.276887 | FT50: 15.426257 | FU50: 19.214781 | FV50: 20.463383 | FW50: 22.658739 | FX50: 22.198635 | FY50: 21.462963 | FZ50: 15.709677 | GA50: 12.334483 | GB50: 8.6279645 | GC50: 9.0104548 | GD50: 11.589904 | GE50: 14.380977 | GF50: 15.139363 | GG50: 16.373235 | GH50: 20.503683 | GI50: 22.767003 | GJ50: 21.565803 | GK50: 19.809197 | GL50: 17.833442 | GM50: 13.26721 | GN50: 10.505129 | GO50: 8.1616254 | GP50: 9.8652786 | GQ50: 12.314261 | GR50: 14.511323 | GS50: 15.633923 | GT50: 19.537263 | GU50: 22.453155 | GV50: 22.270816 | GW50: 21.400107 | GX50: 20.8329 | GY50: 12.650932 | GZ50: 8.86802 | HA50: 10.286756 | HB50: 11.616846 | HC50: 12.596609 | HD50: 18.004322 | HE50: 19.336626 | HF50: 20.764333 | HG50: 22.599637 | HH50: 21.439993 | HI50: 19.82701 | HJ50: 16.318699 | HK50: 13.946851 | HL50: 10.191458 | HM50: 6.9391821 | HN50: 10.628658 | HO50: 14.473582 | HP50: 16.552942 | HQ50: 19.945132 | HR50: 20.530637 | HS50: 22.906973 | HT50: 22.510715 | HU50: 20.718162 | HV50: 17.324667 | HW50: 14.435742 | HX50: 9.9825743 | HY50: 9.8145978 | HZ50: 10.802444 | IA50: 14.58853 | IB50: 17.589046 | IC50: 19.58103 | ID50: 20.640915 | IE50: 22.752443 | IF50: 21.931183 | IG50: 21.636914 | IH50: 18.133486 | II50: 15.84408 | IJ50: 13.456969
A51: 11 | B51: South Susuin West | C51: Temperature | D51: Degrees Celsius | E51: 9.8602032 | F51: 11.012046 | G51: 11.578503 | H51: 13.539047 | I51: 15.524281 | J51: 18.71313 | K51: 21.217116 | L51: 21.591294 | M51: 20.069733 | N51: 17.7607 | O51: 15.17061 | P51: 12.593981 | Q51: 10.207797 | R51: 11.295793 | S51: 12.934674 | T51: 15.265233 | U51: 17.586984 | V51: 20.132869 | W51: 21.657584 | X51: 22.025265 | Y51: 20.370577 | Z51: 17.854278 | AA51: 13.8653 | AB51: 11.226455 | AC51: 9.6059387 | AD51: 11.054414 | AE51: 13.501261 | AF51: 16.05662 | AG51: 19.572042 | AH51: 21.237607 | AI51: 21.500761 | AJ51: 21.46519 | AK51: 21.114573 | AL51: 17.639071 | AM51: 15.388543 | AN51: 10.441465 | AO51: 9.3999032 | AP51: 10.339543 | AQ51: 13.015765 | AR51: 14.18985 | AS51: 16.72859 | AT51: 18.657883 | AU51: 21.994723 | AV51: 22.552268 | AW51: 21.241713 | AX51: 16.727403 | AY51: 13.509 | AZ51: 9.3473677 | BA51: 8.0575065 | BB51: 9.5022143 | BC51: 11.5183 | BD51: 13.76965 | BE51: 16.403745 | BF51: 19.037523 | BG51: 21.147916 | BH51: 20.679826 | BI51: 19.975687 | BJ51: 18.535948 | BK51: 15.337753 | BL51: 10.712919 | BM51: 9.9439839 | BN51: 11.195871 | BO51: 12.260668 | BP51: 15.940437 | BQ51: 18.271758 | BR51: 20.601041 | BS51: 20.837955 | BT51: 21.320003 | BU51: 20.092843 | BV51: 17.977706 | BW51: 13.26801 | BX51: 10.774313 | BY51: 9.2130161 | BZ51: 9.790575 | CA51: 13.310571 | CB51: 15.23779 | CC51: 19.215003 | CD51: 21.040027 | CE51: 21.044274 | CF51: 20.712894 | CG51: 19.73515 | CH51: 17.9693 | CI51: 15.935337 | CJ51: 10.747839 | CK51: 10.038758 | CL51: 10.321143 | CM51: 13.086087 | CN51: 15.834773 | CO51: 17.127303 | CP51: 20.235257 | CQ51: 21.440965 | CR51: 20.698071 | CS51: 20.343027 | CT51: 17.615632 | CU51: 14.558093 | CV51: 11.599719 | CW51: 10.370181 | CX51: 11.504996 | CY51: 14.118035 | CZ51: 15.29248 | DA51: 17.150574 | DB51: 20.374017 | DC51: 22.303974 | DD51: 22.01631 | DE51: 21.059043 | DF51: 18.632468 | DG51: 14.50614 | DH51: 11.237187 | DI51: 9.4711355 | DJ51: 10.786493 | DK51: 14.148865 | DL51: 16.156 | DM51: 18.630365 | DN51: 20.212341 | DO51: 21.444861 | DP51: 21.419568 | DQ51: 21.113227 | DR51: 17.752253 | DS51: 14.202503 | DT51: 10.901965 | DU51: 9.2370419 | DV51: 11.486782 | DW51: 14.866784 | DX51: 15.26631 | DY51: 18.035342 | DZ51: 19.759923 | EA51: 22.0571 | EB51: 21.355558 | EC51: 19.63836 | ED51: 17.898777 | EE51: 15.18653 | EF51: 11.376206 | EG51: 10.163013 | EH51: 11.012707 | EI51: 11.025765 | EJ51: 12.632467 | EK51: 18.127913 | EL51: 20.692807 | EM51: 22.753735 | EN51: 21.327432 | EO51: 19.72839 | EP51: 17.153771 | EQ51: 15.180137 | ER51: 10.914248 | ES51: 8.451171 | ET51: 10.858296 | EU51: 14.028613 | EV51: 15.80176 | EW51: 17.623987 | EX51: 19.80785 | EY51: 21.673494 | EZ51: 21.087403 | FA51: 20.602037 | FB51: 16.961535 | FC51: 15.149087 | FD51: 10.639294 | FE51: 8.4579452 | FF51: 9.501425 | FG51: 13.331197 | FH51: 14.881943 | FI51: 17.605365 | FJ51: 19.748383 | FK51: 21.209848 | FL51: 20.835148 | FM51: 18.680053 | FN51: 15.513322 | FO51: 12.856687 | FP51: 9.7375581 | FQ51: 8.7403516 | FR51: 10.453696 | FS51: 13.053213 | FT51: 15.17774 | FU51: 17.9653 | FV51: 19.5377 | FW51: 20.99649 | FX51: 20.760684 | FY51: 20.791137 | FZ51: 17.090284 | GA51: 14.129853 | GB51: 9.9683161 | GC51: 9.4554161 | GD51: 11.185514 | GE51: 13.367297 | GF51: 14.906107 | GG51: 16.481058 | GH51: 19.732977 | GI51: 20.602874 | GJ51: 19.931381 | GK51: 19.887417 | GL51: 18.402523 | GM51: 14.55484 | GN51: 10.940035 | GO51: 8.7408851 | GP51: 10.141746 | GQ51: 11.090955 | GR51: 14.06869 | GS51: 15.905913 | GT51: 18.551317 | GU51: 21.263345 | GV51: 20.890074 | GW51: 20.551533 | GX51: 20.4827 | GY51: 14.20378 | GZ51: 10.489474 | HA51: 9.7222516 | HB51: 11.15386 | HC51: 12.311241 | HD51: 14.396272 | HE51: 17.411867 | HF51: 18.946625 | HG51: 20.813124 | HH51: 21.321781 | HI51: 19.654941 | HJ51: 17.961416 | HK51: 16.485002 | HL51: 13.686233 | HM51: 9.2890843 | HN51: 10.726984 | HO51: 13.512914 | HP51: 16.23933 | HQ51: 18.238909 | HR51: 18.991559 | HS51: 22.129059 | HT51: 21.062959 | HU51: 21.450068 | HV51: 17.125637 | HW51: 14.427329 | HX51: 11.268443 | HY51: 10.301006 | HZ51: 12.211615 | IA51: 14.717155 | IB51: 16.07482 | IC51: 18.509536 | ID51: 19.653592 | IE51: 21.457611 | IF51: 21.307402 | IG51: 21.001848 | IH51: 19.943022 | II51: 16.328052 | IJ51: 13.854416
